<?xml version="1.0"?>
<robot xmlns:xacro="http://www.ros.org/wiki/xacro" name="lizi_robot" description="lizi Robot">
<xacro:property name="M_PI" value="3.1415926535897931"/>

  <link
    name="base_link">
    <inertial>
      <origin
        xyz="0.0 0.0 0.04047"
        rpy="0 0 0" />
      <mass
        value="5.47025" />
      <inertia
        ixx="0.004176"
        ixy="0.00013487"
        ixz="-0.00050843"
        iyy="0.0083952"
        iyz="8.2807E-06"
        izz="0.0098763" />
    </inertial>
    <visual>
      <origin
        xyz="0 0 0"
        rpy="0 0 0" />
      <geometry>
        <mesh
          filename="package://robotican_lizi/description/meshes/base_link.STL" />
      </geometry>
      <material
        name="">
        <color
          rgba="0.0 1.0 0.0 1" />
      </material>
    </visual>
    <collision>
      <origin
        xyz="0 0 0"
        rpy="0 0 0" />
      <geometry>
        <mesh
          filename="package://robotican_lizi/description/meshes/base_link.STL" />
      </geometry>
    </collision>
  </link>
  <link
    name="base_footprint" />
  <joint
    name="footprint_joint"
    type="fixed">
    <origin
      xyz="0 0 0.0762"
      rpy="0 0 0" />
    <parent
      link="base_footprint" />
    <child
      link="base_link" />
    <axis
      xyz="0 0 0" />
  </joint>
  <link
    name="laser_link">
    <visual>
      <origin
        xyz="0 0 0"
        rpy="0 0 0" />
      <geometry>
        <mesh
          filename="package://robotican_lizi/description/meshes/laser_link.STL" />
      </geometry>
      <material
        name="">
        <color
          rgba="0.0 0.0 0.0 1" />
      </material>
    </visual>
    <collision>
      <origin
        xyz="0 0 0"
        rpy="0 0 0" />
      <geometry>
        <mesh
          filename="package://robotican_lizi/description/meshes/laser_link.STL" />
      </geometry>
    </collision>
  </link>
  <joint
    name="laser_joint"
    type="fixed">
    <origin
      xyz="0.1495 0 0.079"
      rpy="0 0 0" />
    <parent
      link="base_link" />
    <child
      link="laser_link" />
    <axis
      xyz="0 0 0" />
  </joint>
  <link
    name="sr300_link">
    <visual>
      <origin
        xyz="0 0 0"
        rpy="0 0 0" />
      <geometry>
        <mesh
          filename="package://robotican_lizi/description/meshes/sr300_link.STL" />
      </geometry>
      <material
        name="black">
        <color
          rgba="0.0 0.0 0.0 1" />
      </material>
    </visual>
    <collision>
      <origin
        xyz="0 0 0"
        rpy="0 0 0" />
      <geometry>
        <mesh
          filename="package://robotican_lizi/description/meshes/sr300_link.STL" />
      </geometry>
    </collision>
  </link>
  <joint
    name="sr300_joint"
    type="fixed">
    <origin
      xyz="0.19382 0 0.10646"
      rpy="0 0 0" />
    <parent
      link="base_link" />
    <child
      link="sr300_link" />
    <axis
      xyz="0 0 0" />
  </joint>
  <link
    name="left_urf_link" />
  <joint
    name="left_urf_joint"
    type="fixed">
    <origin
      xyz="0.014542 0.1055 0.0902"
      rpy="0 0 1.5708" />
    <parent
      link="base_link" />
    <child
      link="left_urf_link" />
    <axis
      xyz="0 0 0" />
  </joint>
  <link
    name="rear_urf_link" />
  <joint
    name="rear_urf_joint"
    type="fixed">
    <origin
      xyz="-0.18 0 0.0902"
      rpy="0 0 3.1416" />
    <parent
      link="base_link" />
    <child
      link="rear_urf_link" />
    <axis
      xyz="0 0 0" />
  </joint>
  <link
    name="right_urf_link" />
  <joint
    name="right_urf_joint"
    type="fixed">
    <origin
      xyz="0.014542 -0.1055 0.0902"
      rpy="0 0 -1.5708" />
    <parent
      link="base_link" />
    <child
      link="right_urf_link" />
    <axis
      xyz="0 0 0" />
  </joint>
  <link
    name="FL_wheel_link">
    <inertial>
      <origin
        xyz="-9.1354E-06 -0.001115 4.3697E-07"
        rpy="0 0 0" />
      <mass
        value="0.20156" />
      <inertia
        ixx="0.00032875"
        ixy="8.8617E-09"
        ixz="8.2109E-12"
        iyy="0.00062398"
        iyz="5.8123E-10"
        izz="0.00032873" />
    </inertial>
    <visual>
      <origin
        xyz="0 0 0"
        rpy="0 0 0" />
      <geometry>
        <mesh
          filename="package://robotican_lizi/description/meshes/wheel_link.STL" />
      </geometry>
      <material
        name="">
        <color
          rgba="0.0 0.0 0.0 1" />
      </material>
    </visual>
    <collision>
      <origin
        xyz="0 0 0"
        rpy="${M_PI/2} 0 0" />
      <geometry>
       
       <!--    <mesh filename="package://robotican_lizi/description/meshes/wheel_link.STL" /> -->
  <cylinder  length="0.05" radius="0.0762"/> 
      </geometry>
    </collision>
  </link>
  <joint
    name="FL_wheel_joint"
    type="continuous">
    <origin
      xyz="0.13 0.13321 0"
      rpy="0 0 0" />
    <parent
      link="base_link" />
    <child
      link="FL_wheel_link" />
    <axis
      xyz="0 1 0" />
  </joint>
  <link
    name="RL_wheel_link">
    <inertial>
      <origin
        xyz="-9.1354E-06 -0.001115 4.3697E-07"
        rpy="0 0 0" />
      <mass
        value="0.20156" />
      <inertia
        ixx="0.00032875"
        ixy="8.8617E-09"
        ixz="8.2109E-12"
        iyy="0.00062398"
        iyz="5.8123E-10"
        izz="0.00032873" />
    </inertial>
    <visual>
      <origin
        xyz="0 0 0"
        rpy="0 0 0" />
      <geometry>
        <mesh
          filename="package://robotican_lizi/description/meshes/wheel_link.STL" />
      </geometry>
      <material
        name="">
        <color
          rgba="0.0 0.0 0.0 1" />
      </material>
    </visual>
    <collision>
      <origin
        xyz="0 0 0"
         rpy="${M_PI/2} 0 0" />
      <geometry>
       <!--    <mesh filename="package://robotican_lizi/description/meshes/wheel_link.STL" /> -->
  <cylinder  length="0.05" radius="0.0762"/> 
      </geometry>
    </collision>
  </link>
  <joint
    name="RL_wheel_joint"
    type="continuous">
    <origin
      xyz="-0.13 0.13321 0"
      rpy="0 0 0" />
    <parent
      link="base_link" />
    <child
      link="RL_wheel_link" />
    <axis
      xyz="0 1 0" />
  </joint>
  <link
    name="FR_wheel_link">
    <inertial>
      <origin
        xyz="9.1354E-06 0.001115 4.3696E-07"
        rpy="0 0 0" />
      <mass
        value="0.20156" />
      <inertia
        ixx="0.00032875"
        ixy="8.8617E-09"
        ixz="-8.2128E-12"
        iyy="0.00062398"
        iyz="-5.8127E-10"
        izz="0.00032873" />
    </inertial>
    <visual>
      <origin
        xyz="0 0 0"
        rpy="0 0 0" />
      <geometry>
        <mesh
          filename="package://robotican_lizi/description/meshes/wheel_link.STL" />
      </geometry>
      <material
        name="">
        <color
          rgba="0.0 0.0 0.0 1" />
      </material>
    </visual>
    <collision>
      <origin
        xyz="0 0 0"
     rpy="${M_PI/2} 0 0" />
      <geometry>
       <!--    <mesh filename="package://robotican_lizi/description/meshes/wheel_link.STL" /> -->
  <cylinder  length="0.05" radius="0.0762"/> 
      </geometry>
    </collision>
  </link>
  <joint
    name="FR_wheel_joint"
    type="continuous">
    <origin
      xyz="0.13 -0.13321 0"
      rpy="0 0 0" />
    <parent
      link="base_link" />
    <child
      link="FR_wheel_link" />
    <axis
      xyz="0 1 0" />
  </joint>
  <link
    name="RR_wheel_link">
    <inertial>
      <origin
        xyz="-9.1354E-06 0.001115 -4.3696E-07"
        rpy="0 0 0" />
      <mass
        value="0.20156" />
      <inertia
        ixx="0.00032875"
        ixy="-8.8617E-09"
        ixz="-8.2125E-12"
        iyy="0.00062398"
        iyz="5.8127E-10"
        izz="0.00032873" />
    </inertial>
    <visual>
      <origin
        xyz="0 0 0"
        rpy="0 0 0" />
      <geometry>
        <mesh
          filename="package://robotican_lizi/description/meshes/wheel_link.STL" />
      </geometry>
      <material
        name="">
        <color
          rgba="0.0 0.0 0.0 1" />
      </material>
    </visual>
    <collision>
      <origin
        xyz="0 0 0"
        rpy="${M_PI/2} 0 0" />
      <geometry>
       <!--    <mesh filename="package://robotican_lizi/description/meshes/wheel_link.STL" /> -->
  <cylinder  length="0.05" radius="0.0762"/> 
      </geometry>
    </collision>
  </link>
  <joint
    name="RR_wheel_joint"
    type="continuous">
    <origin
      xyz="-0.13 -0.13321 0"
      rpy="0 0 0" />
    <parent
      link="base_link" />
    <child
      link="RR_wheel_link" />
    <axis
      xyz="0 1 0" />
  </joint>
  <link
    name="front_camera_link" />
  <joint
    name="front_camera_joint"
    type="fixed">
    <origin
      xyz="0.17275 0.068 0.0202"
      rpy="0 0 0" />
    <parent
      link="base_link" />
    <child
      link="front_camera_link" />
    <axis
      xyz="0 0 0" />
  </joint>
</robot>
