<?xml version="1.0"?>
<robot name="komodo_torso" description="Komodo Torso" xmlns:xacro="http://www.ros.org/wiki/xacro">

      <link name="base_footprint"/>
  
 <joint name="base_footprint_joint" type="fixed">
    <parent link="base_footprint"/>
    <child link="base_link"/>
    <origin xyz="0.00 0.00 0.1275" rpy="0.0 0.0 0.0"/>
  </joint> 

  <link
    name="base_link">
    <inertial>
      <origin
        xyz="0.0030152 0.00057861 0.0749"
        rpy="0 0 0" />
      <mass
        value="6.0" /> <!--20.0058-->
      <inertia
        ixx="0.025582"
        ixy="0.0010034"
        ixz="-0.0041152"
        iyy="0.086418"
        iyz="-3.8058E-05"
        izz="0.091994" />
    </inertial>
    <visual>
      <origin
        xyz="0 0 0"
        rpy="0 0 0" />
      <geometry>
        <mesh
          filename="package://robotican_komodo/description/meshes/base_link.STL" />
      </geometry>
      <material
        name="">
        <color
          rgba="0.79216 0.81961 0.93333 1" />
      </material>
    </visual>
    <collision>
      <origin
        xyz="0 0 0"
        rpy="0 0 0" />
      <geometry>
        <mesh
          filename="package://robotican_komodo/description/meshes/base_link.STL" />
      </geometry>
    </collision>
  </link>


  <link name="arm_base_link">
    <inertial>
      <origin xyz="0.0787832367713514 1.63894955207658E-05 0.30372182598738" rpy="0 0 0" />
      <mass value="5.82785061945851" />
      <inertia
        ixx="0.262040399352781"
        ixy="-1.20613586206922E-05"
        ixz="0.0219696026578"
        iyy="0.271705564666912"
        iyz="3.10612186063073E-05"
        izz="0.0337682852586326" />
    </inertial>
    <visual>
      <origin xyz="0 0 0" rpy="0 0 0" />
      <geometry>
        <mesh filename="package://robotican_komodo/description/meshes/arm_base_link.STL" />
      </geometry>
      <material name="">
        <color rgba="0.4 0.4 0.4 1" />
      </material>
    </visual>
  <collision>
      <origin xyz="0 0 0" rpy="0 0 0" />
      <geometry>
        <mesh filename="package://robotican_komodo/description/meshes/arm_base_link.STL" />
      </geometry>
    </collision> 
  </link>

  <joint name="arm_base_joint" type="fixed">
    <origin xyz="-0.112249972183238 0 0.167160698455407" rpy="0 0 0" />
    <parent link="base_link" />
    <child link="arm_base_link" />
    <axis xyz="0 0 0" />  
  </joint>
  
   <link
    name="torso_link">
    <inertial>
      <origin
        xyz="0.0954671716579415 1.91586249009607E-06 -0.0185743175743276"
        rpy="0 0 0" />
      <mass
        value="1.09057945344451" />
      <inertia
        ixx="0.000835857275985966"
        ixy="5.81870910353681E-08"
        ixz="-3.13493979506258E-05"
        iyy="0.00128840659932805"
        iyz="1.45397132642805E-07"
        izz="0.00136461371089342" />
    </inertial>
    <visual>
      <origin
        xyz="0 0 0"
        rpy="0 0 0" />
      <geometry>
        <mesh
          filename="package://robotican_komodo/description/meshes/torso_link.STL" />
      </geometry>
      <material
        name="">
        <color
          rgba="0.35 0.35 0.35 1" />
      </material>
    </visual>
    <collision>
      <origin
        xyz="0 0 0"
        rpy="0 0 0" />
      <geometry>
        <mesh
          filename="package://robotican_komodo/description/meshes/torso_link.STL" />
      </geometry>
    </collision> 
  </link>
  <joint
    name="torso_joint"
    type="prismatic"> <!--prismatic-->
    <origin
      xyz="0.101457996026178 0 0.0740000000000002"
      rpy="0 0 0" />
    <parent
      link="arm_base_link" />
    <child
      link="torso_link" />
    <axis
      xyz="0 0 1" />
   <limit
	lower="0"
	upper="0.45"
	effort="70"
	velocity="0.012" />
  </joint>

  <joint
    name="base_rotation_joint"
    type="revolute">
    <origin
      xyz="0.113 0 -0.00400000000000003"
      rpy="0 0 0" />
    <parent
      link="torso_link" />
    <child
      link="base_rotation_link" />
    <axis
      xyz="0 0 1" />
    <limit
      lower="-3.14"
      upper="3.14"
      effort="10"
      velocity="1.0" />
  </joint>
  <link name="base_rotation_link">
    <inertial>
      <origin 
        rpy="0 0 0" 
        xyz="-6.93889390390723E-17 1.46538271444029E-17 0.0623331826247039"/>
      <mass 
        value="1.4054258533062"/>
      <inertia 
        ixx="0.00159425912810341" 
        ixy="-8.40269196653518E-08" 
        ixz="-1.60925604895535E-19" 
        iyy="0.000605522001732049" 
        iyz="-6.08768470792684E-19" 
        izz="0.00123388334665811"/>
    </inertial>
    <visual>
      <origin rpy="0 0 0" xyz="0 0 0"/>
      <geometry>
        <mesh filename="package://robotican_arm/meshes/base_rotation_link.STL"/>
      </geometry>
      <material name="">
        <color rgba="0.3 0.3 0.3 1"/>
      </material>
    </visual>
    <collision>
      <origin rpy="0 0 0" xyz="0 0 0"/>
      <geometry>
        <mesh filename="package://robotican_arm/meshes/base_rotation_link.STL"/>
      </geometry>
    </collision> 
  </link>

  <link name="shoulder_link">
    <inertial>
      <origin rpy="0 0 0" xyz="4.66247777455853E-06 -9.82289263772941E-05 0.0772888499398813"/>
      <mass value="0.191480823048406"/>
      <inertia ixx="0.00107301595696304" ixy="-2.9789063890745E-07" ixz="-2.01216953964121E-08" iyy="0.000975953125213584" iyz="-1.19601921452086E-06" izz="0.000217659789393094"/>
    </inertial>
    <visual>
      <origin rpy="0 0 0" xyz="0 0 0"/>
      <geometry>
        <mesh filename="package://robotican_arm/meshes/shoulder_link.STL"/>
      </geometry>
      <material name="">
        <color rgba="0.4 0.4 0.4 1"/>
      </material>
    </visual>
    <collision>
      <origin rpy="0 0 0" xyz="0 0 0"/>
      <geometry>
        <mesh filename="package://robotican_arm/meshes/shoulder_link.STL"/>
      </geometry>
    </collision> 
  </link>
  <joint name="shoulder_joint" type="revolute">
    <origin rpy="-4.20159904047482E-15 -5.97509793174248E-16 9.93431320775303E-15" xyz="0 0 0.0835"/>
    <parent link="base_rotation_link"/>
    <child link="shoulder_link"/>
    <axis xyz="0 1 0"/>
    <limit effort="2000" lower="-9.9E-07" upper="1.57" velocity="1.0"/>
  </joint>
  <link name="elbow1_link">
    <inertial>
      <origin rpy="0 0 0" xyz="3.38829306132937E-05 2.66620552362602E-06 0.0239321015118659"/>
      <mass value="0.759959116000226"/>
      <inertia ixx="0.0011156254663426" ixy="3.16193221175592E-07" ixz="2.89169705133133E-06" iyy="0.00114606034071406" iyz="-8.11914906919631E-08" izz="0.000237163435713384"/>
    </inertial>
    <visual>
      <origin rpy="0 0 0" xyz="0 0 0"/>
      <geometry>
        <mesh filename="package://robotican_arm/meshes/elbow1_link.STL"/>
        <!-- Simplified -->
      </geometry>
      <material name="">
        <color rgba="0.3 0.3 0.3 1"/>
      </material>
    </visual>
    <collision>
      <origin rpy="0 0 0" xyz="0 0 0"/>
      <geometry>
        <mesh filename="package://robotican_arm/meshes/elbow1_link.STL"/>
      </geometry>
    </collision> 
  </link>
  <joint name="elbow1_joint" type="revolute">
    <origin rpy="1.44504380352115E-15 1.11628850952447E-06 -9.93431159466724E-15" xyz="0 -0.000251155668931501 0.266305434894181"/>
    <parent link="shoulder_link"/>
    <child link="elbow1_link"/>
    <axis xyz="-0.999999999998754 0 0"/>
    <limit effort="100" lower="-3.14" upper="3.14" velocity="1.0"/>
  </joint>
  <link name="elbow2_link">
    <inertial>
      <origin rpy="0 0 0" xyz="0.000512284668490459 -2.29084833272284E-05 0.0885118785637893"/>
      <mass value="1.12138857800426"/>
      <inertia ixx="0.0011156254663426" ixy="3.04261287700186E-07" ixz="-1.22468079415109E-06" iyy="0.0110437302875007" iyz="-7.91547787630536E-05" izz="0.000331598270284794"/>
    </inertial>
    <visual>
      <origin rpy="0 0 0" xyz="0 0 0"/>
      <geometry>
        <mesh filename="package://robotican_arm/meshes/elbow2_link.STL"/>
        <!-- Simplified -->
      </geometry>
      <material name="">
        <color rgba="0.4 0.4 0.4 1"/>
      </material>
    </visual>
    <collision>
      <origin rpy="0 0 0" xyz="0 0 0"/>
      <geometry>
        <mesh filename="package://robotican_arm/meshes/elbow2_link.STL"/>
      </geometry>
    </collision> 
  </link>
  <joint name="elbow2_joint" type="revolute">
    <origin rpy="-4.51048856041191E-16 3.35869632765754E-16 0" xyz="0 0 0.22399999999847"/>
    <parent link="elbow1_link"/>
    <child link="elbow2_link"/>
    <axis xyz="0 1 0"/>
    <limit effort="10" lower="-3.14" upper="3.14" velocity="1.0"/>
  </joint>
  <link name="wrist_link">
    <inertial>
      <origin rpy="0 0 0" xyz="0.0303673809619356 4.00707611352118E-10 0.000140374211043737"/>
      <mass value="0.717337417215465"/>
      <inertia ixx="0.000486392340366094" ixy="4.20757000035677E-12" ixz="-3.91843889020299E-06" iyy="0.000211170064630335" iyz="2.79335159568522E-12" izz="0.000437528795624211"/>
    </inertial>
    <visual>
      <origin rpy="0 0 0" xyz="0 0 0"/>
      <geometry>
        <mesh filename="package://robotican_arm/meshes/wrist_link.STL"/>
        <!-- Simplified -->
      </geometry>
      <material name="">
        <color rgba="0.4 0.4 0.4 1"/>
      </material>
    </visual>
    <collision>
      <origin rpy="0 0 0" xyz="0 0 0"/>
      <geometry>
        <mesh filename="package://robotican_arm/meshes/wrist_link.STL"/>
      </geometry>
    </collision> 
  </link>
  <joint name="wrist_joint" type="revolute">
    <origin rpy="0 0 0" xyz="0.0131002732116043 0 0.244749985376465"/>
    <parent link="elbow2_link"/>
    <child link="wrist_link"/>
    <axis xyz="0 0 0.999999999998754"/>
    <limit effort="10" lower="-3.14" upper="3.14" velocity="1.0"/>
  </joint>
  
  <link name="gripper_link"/>

  <joint name="gripper_joint" type="fixed">
  <origin xyz="0 0 0.06" rpy="0 -1.570796327 0"/>
  <parent link="wrist_link"/>
  <child link="gripper_link"/>
  </joint>
  
  <link name="left_finger_link">
    <inertial>
      <origin rpy="0 0 0" xyz="-6.10622663543836E-16 0.0205697573116852 0.0301832532936965"/>
      <mass value="0.0111981711598485"/>
      <inertia ixx="0.000486392340366094" ixy="4.20757000035677E-12" ixz="-3.91843889020299E-06" iyy="0.000211170064630335" iyz="2.79335159568522E-12" izz="0.000437528795624211"/>
    </inertial>
    <visual>
      <origin rpy="0 0 0" xyz="0 0 0"/>
      <geometry>
        <mesh filename="package://robotican_arm/meshes/left_finger_link.STL"/>
        <!-- Simplified -->
      </geometry>
      <material name="">
        <color rgba="0.4 0.4 0.4 1"/>
      </material>
    </visual>
    <collision>
      <origin rpy="0 0 0" xyz="0 0 0"/>
      <geometry>
        <mesh filename="package://robotican_arm/meshes/left_finger_link.STL"/>
      </geometry>
    </collision> 
  </link>
  <joint name="left_finger_joint" type="revolute">
    <origin rpy="0.205 0 0.0" xyz="-0.000250000000000111 0.021 0.0422500000000001"/>
    <parent link="wrist_link"/>
    <child link="left_finger_link"/>
    <axis xyz="1 0 0"/>
    <limit effort="3.1" lower="-1.57" upper="1.57" velocity="2.0"/>
  </joint>
  <link name="right_finger_link">
    <inertial>
      <origin rpy="0 0 0" xyz="2.77555756156289E-16 -0.0205697573116854 0.0301832532936965"/>
      <mass value="0.0111981711598485"/>
      <inertia ixx="0.000486392340366094" ixy="4.20757000035677E-12" ixz="-3.91843889020299E-06" iyy="0.000211170064630335" iyz="2.79335159568522E-12" izz="0.000437528795624211"/>
    </inertial>
    <visual>
      <origin rpy="0 0 0" xyz="0 0 0"/>
      <geometry>
        <mesh filename="package://robotican_arm/meshes/right_finger_link.STL"/>
        <!-- Simplified -->
      </geometry>
      <material name="">
        <color rgba="0.4 0.4 0.4 1"/>
      </material>
    </visual>
    <collision>
      <origin rpy="0 0 0" xyz="0 0 0"/>
      <geometry>
        <mesh filename="package://robotican_arm/meshes/right_finger_link.STL"/>
      </geometry>
    </collision> 
  </link>
  <joint name="right_finger_joint" type="revolute">
    <origin rpy="-0.205 0 0" xyz="-0.00024999999999889 -0.021 0.0422499999999999"/>
    <parent link="wrist_link"/>
    <child link="right_finger_link"/>
    <axis xyz="1 0 0"/>
    <limit effort="3.1" lower="-1.57" upper="1.57" velocity="2.0"/>
  </joint>


</robot>
